<?xml version="1.0" ?>
<!-- =================================================================================== -->
<!-- |    This document was autogenerated by xacro from urdf/AV_car.xacro.urdf         | -->
<!-- |    EDITING THIS FILE BY HAND IS NOT RECOMMENDED                                 | -->
<!-- =================================================================================== -->
<robot name="FYP_car">
  <link name="base_link"/>
  <joint name="chassis_joint" type="fixed">
    <parent link="base_link"/>
    <child link="chassis_link"/>
    <origin xyz="0 0 0.13"/>
  </joint>
  <link name="chassis_link">
    <visual>
      <origin rpy="1.5707963267948966 0 1.5707963267948966" xyz="0 -0.3333333333333333 0.75"/>
      <geometry>
        <mesh filename="package://car_model/meshes/chassis.stl" scale="0.002 0.001 0.001"/>
      </geometry>
      <material name="grey">
        <color rgba="0.5 0.5 0.5 0.8"/>
      </material>
    </visual>
    <!--
		<visual>
			<origin xyz="${chassis_length/4} 0 ${chassis_height/2}" />
			<geometry>
				<box size="${chassis_length/2 - arc_distance} ${chassis_width_top} ${chassis_height}"/>
			</geometry>
		</visual>
		<visual>
			<origin xyz="${-chassis_length/4} 0 ${chassis_height/2}" />
			<geometry>
				<box size="1.35 0.8 1.5"/>
			</geometry>
		</visual>
		-->
    <collision>
      <origin xyz="0 0 0.75"/>
      <geometry>
        <box size="2.6 0.8 1.5"/>
      </geometry>
    </collision>
    <inertial>
      <mass value="100"/>
      <origin xyz="0 0 0.75"/>
      <inertia ixx="24.1" ixy="0" ixz="0" iyy="75.08" iyz="0" izz="61.67"/>
    </inertial>
  </link>
  <joint name="front_left_wheel_steering_joint" type="revolute">
    <origin rpy="0 0 0" xyz="0.75 0.5 0.16999999999999998"/>
    <parent link="chassis_link"/>
    <child link="front_left_wheel_steering_link"/>
    <axis xyz="0 0 1"/>
    <!-- change effort after you we know the value of torquw -->
    <limit effort="100" lower="-0.24958208303518914" upper="0.24958208303518914" velocity="5.56"/>
  </joint>
  <link name="front_left_wheel_steering_link">
    <visual>
      <geometry>
        <cylinder length="0.06" radius="0.035"/>
      </geometry>
      <origin rpy="0 0 0" xyz="0.0 0.0 0.0"/>
      <!-- Make it transparent later -->
      <material name="white">
        <color rgba="0 0 0 0.25"/>
      </material>
    </visual>
    <!-- Change to sphere later if the car drives a bit rough -->
    <collision>
      <geometry>
        <cylinder length="0.06" radius="0.035"/>
      </geometry>
      <origin rpy="0 0 0" xyz="0.0 0.0 0.0"/>
    </collision>
    <inertial>
      <mass value="0.5"/>
      <origin rpy="0 0 0" xyz="0.0 0.0 0.0"/>
      <inertia ixx="7.62e-04" ixy="0.0" ixz="0.0" iyy="7.62e-04" iyz="0.0" izz="1.225e-03"/>
    </inertial>
  </link>
  <joint name="front_left_wheel_joint" type="continuous">
    <origin rpy="-1.5707963267948966 0 0" xyz="0 0.07 0"/>
    <parent link="front_left_wheel_steering_link"/>
    <child link="front_left_wheel_link"/>
    <axis xyz="0 0 1"/>
  </joint>
  <link name="front_left_wheel_link">
    <visual>
      <geometry>
        <cylinder length="0.07" radius="0.3"/>
      </geometry>
      <origin rpy="0 0 0" xyz="0.0 0.0 0.0"/>
      <material name="black">
        <color rgba="0 0 0 0.5"/>
      </material>
    </visual>
    <!-- Change to sphere later if the car drives a bit rough -->
    <collision>
      <geometry>
        <cylinder length="0.07" radius="0.3"/>
      </geometry>
      <origin rpy="0 0 0" xyz="0.0 0.0 0.0"/>
    </collision>
    <inertial>
      <mass value="5.0"/>
      <origin rpy="0 0 0" xyz="0.0 0.0 0.0"/>
      <inertia ixx="0.452" ixy="0.0" ixz="0.0" iyy="0.452" iyz="0.0" izz="0.9"/>
    </inertial>
  </link>
  <joint name="front_right_wheel_steering_joint" type="revolute">
    <origin rpy="0 0 0" xyz="0.75 -0.5 0.16999999999999998"/>
    <parent link="chassis_link"/>
    <child link="front_right_wheel_steering_link"/>
    <axis xyz="0 0 1"/>
    <!-- change effort after you we know the value of torquw -->
    <limit effort="100" lower="-0.24958208303518914" upper="0.24958208303518914" velocity="5.56"/>
  </joint>
  <link name="front_right_wheel_steering_link">
    <visual>
      <geometry>
        <cylinder length="0.06" radius="0.035"/>
      </geometry>
      <origin rpy="0 0 0" xyz="0.0 0.0 0.0"/>
      <!-- Make it transparent later -->
      <material name="white">
        <color rgba="0 0 0 0.25"/>
      </material>
    </visual>
    <!-- Change to sphere later if the car drives a bit rough -->
    <collision>
      <geometry>
        <cylinder length="0.06" radius="0.035"/>
      </geometry>
      <origin rpy="0 0 0" xyz="0.0 0.0 0.0"/>
    </collision>
    <inertial>
      <mass value="0.5"/>
      <origin rpy="0 0 0" xyz="0.0 0.0 0.0"/>
      <inertia ixx="7.62e-04" ixy="0.0" ixz="0.0" iyy="7.62e-04" iyz="0.0" izz="1.225e-03"/>
    </inertial>
  </link>
  <joint name="front_right_wheel_joint" type="continuous">
    <origin rpy="1.5707963267948966 0 0" xyz="0 -0.07 0"/>
    <parent link="front_right_wheel_steering_link"/>
    <child link="front_right_wheel_link"/>
    <axis xyz="0 0 1"/>
  </joint>
  <link name="front_right_wheel_link">
    <visual>
      <geometry>
        <cylinder length="0.07" radius="0.3"/>
      </geometry>
      <origin rpy="0 0 0" xyz="0.0 0.0 0.0"/>
      <material name="black">
        <color rgba="0 0 0 0.5"/>
      </material>
    </visual>
    <!-- Change to sphere later if the car drives a bit rough -->
    <collision>
      <geometry>
        <cylinder length="0.07" radius="0.3"/>
      </geometry>
      <origin rpy="0 0 0" xyz="0.0 0.0 0.0"/>
    </collision>
    <inertial>
      <mass value="5.0"/>
      <origin rpy="0 0 0" xyz="0.0 0.0 0.0"/>
      <inertia ixx="0.452" ixy="0.0" ixz="0.0" iyy="0.452" iyz="0.0" izz="0.9"/>
    </inertial>
  </link>
  <joint name="rear_left_wheel_joint" type="continuous">
    <origin rpy="-1.5707963267948966 0 0" xyz="-0.95 0.47000000000000003 0.16999999999999998"/>
    <parent link="chassis_link"/>
    <child link="rear_left_wheel_link"/>
    <axis xyz="0 0 1"/>
  </joint>
  <link name="rear_left_wheel_link">
    <visual>
      <geometry>
        <cylinder length="0.07" radius="0.3"/>
      </geometry>
      <origin rpy="0 0 0" xyz="0.0 0.0 0.0"/>
      <material name="black">
        <color rgba="0 0 0 0.5"/>
      </material>
    </visual>
    <!-- Change to sphere later if the car drives a bit rough -->
    <collision>
      <geometry>
        <cylinder length="0.07" radius="0.3"/>
      </geometry>
      <origin rpy="0 0 0" xyz="0.0 0.0 0.0"/>
    </collision>
    <inertial>
      <mass value="5.0"/>
      <origin rpy="0 0 0" xyz="0.0 0.0 0.0"/>
      <inertia ixx="0.452" ixy="0.0" ixz="0.0" iyy="0.452" iyz="0.0" izz="0.9"/>
    </inertial>
  </link>
  <joint name="rear_right_wheel_joint" type="continuous">
    <origin rpy="1.5707963267948966 0 0" xyz="-0.95 -0.47000000000000003 0.16999999999999998"/>
    <parent link="chassis_link"/>
    <child link="rear_right_wheel_link"/>
    <axis xyz="0 0 1"/>
  </joint>
  <link name="rear_right_wheel_link">
    <visual>
      <geometry>
        <cylinder length="0.07" radius="0.3"/>
      </geometry>
      <origin rpy="0 0 0" xyz="0.0 0.0 0.0"/>
      <material name="black">
        <color rgba="0 0 0 0.5"/>
      </material>
    </visual>
    <!-- Change to sphere later if the car drives a bit rough -->
    <collision>
      <geometry>
        <cylinder length="0.07" radius="0.3"/>
      </geometry>
      <origin rpy="0 0 0" xyz="0.0 0.0 0.0"/>
    </collision>
    <inertial>
      <mass value="5.0"/>
      <origin rpy="0 0 0" xyz="0.0 0.0 0.0"/>
      <inertia ixx="0.452" ixy="0.0" ixz="0.0" iyy="0.452" iyz="0.0" izz="0.9"/>
    </inertial>
  </link>
  <ros2_control name="IgnitionSystem" type="system">
    <hardware>
      <plugin>ign_ros2_control/IgnitionSystem</plugin>
    </hardware>
    <joint name="front_left_wheel_steering_joint">
      <command_interface name="position"/>
      <state_interface name="position"/>
    </joint>
    <joint name="front_right_wheel_steering_joint">
      <command_interface name="position"/>
      <state_interface name="position"/>
    </joint>
    <joint name="rear_right_wheel_joint">
      <command_interface name="velocity"/>
      <state_interface name="position"/>
      <state_interface name="velocity"/>
    </joint>
    <joint name="rear_left_wheel_joint">
      <command_interface name="velocity"/>
      <state_interface name="position"/>
      <state_interface name="velocity"/>
    </joint>
  </ros2_control>
  <gazebo>
    <plugin filename="ign_ros2_control-system" name="ign_ros2_control::IgnitionROS2ControlPlugin">
      <parameters>/home/user/AV/install/car_model/share/car_model/config/controller.yaml</parameters>
      <controller_manager_name>controller_manager</controller_manager_name>
    </plugin>
  </gazebo>
</robot>
