<?xml version="1.0" ?>
<robot name="vehicle_blue" xmlns:xacro="http://ros.org/wiki/xacro">
	<!-- Variables and Constants -->
	<xacro:property name="chassis_length" value="2.60" />
	<xacro:property name="chassis_width" value="1" />
	<xacro:property name="chassis_height" value="1.5" />
	<xacro:property name="chassis_mass" value="100" />
	<xacro:macro name="cuboid_inertia" params="length width height mass">
		<inertia ixx="${mass*(width*width + height*height)/12}" ixy="0" ixz="0" iyy="${mass*(length*length + height*height)/12}"  iyz="0" izz="${mass*(width*width + length*length)/12}" />
	</xacro:macro>

	<xacro:property name="wheel_base" value="1.7" />
	<xacro:property name="rear_wheel_x" value="-0.8" />
	<xacro:property name="front_wheel_x" value="0.9" />
	<!-- For ground clearance just going to update the collision and visual box of chassis_link -->
	<!-- Model -->
	<link name="base_link" />

	<!-- Chassis -->
	<joint name="chassis_joint" type="fixed">
		<parent link="base_link" />
		<child link="chassis_link" />
		<origin xyz="0 0 0.325" />
	</joint>

	<link name="chassis_link">
		<visual>
			<!-- These numbers are taken from Rviz and are just to align the mesh with the wheels-->
			<origin xyz="0 -0.35 0.435" rpy="${pi/2} 0 ${pi/2}"/>
			<geometry>
				<mesh filename="package://car_model/meshes/chassis.stl" scale="0.002 0.001 0.001"/>
			</geometry>
			<material name="grey">
				<color rgba="0.5 0.5 0.5 0.8" />
			</material>
		</visual>
		<collision>
			<origin xyz="0 0 0.555"/>
			<geometry>
				<box size="${chassis_length} ${chassis_width} ${chassis_height}"/>
			</geometry>
			<material name="grey">
				<color rgba="0.5 0.5 1.0 0.5" />
			</material>
		</collision>
		<inertial>
			<mass value="${chassis_mass}"/>
			<!-- <inertia ixx="0.126164" ixy="0" ixz="0" iyy="0.416519" iyz="0" izz="0.481014"/> -->
			<xacro:cuboid_inertia length="${chassis_length}" width="${chassis_width}" height="${chassis_height}" mass="${chassis_mass}" />
			</inertial> 
	</link>

	<!-- Front Left Steering -->
	<joint name="front_left_wheel_steering_joint" type="revolute">
		<axis xyz="0 0 1" />
		<origin xyz="${front_wheel_x} 0.5 0.02" rpy="0 0 0"/>
		<parent link="chassis_link" />
		<child link="front_left_wheel_steering_link" />
		<limit lower="-0.25" upper="0.25" velocity="1.0" effort="25" />
	</joint>

	<link name="front_left_wheel_steering_link">
		<visual>
			<geometry>
				<cylinder length="0.1" radius="0.03"/>
			</geometry>
			<material name="white">
				<color rgba="1 1 1 0.5" />
			</material>
		</visual>
		<collision>
			<geometry>
				<cylinder length="0.1" radius="0.03"/>
			</geometry>
			<material name="white">
				<color rgba="1 1 1 0.5" />
			</material>
		</collision>
		<inertial>
			<mass value="0.5"/>
			<inertia ixx="0.0153" ixy="0" ixz="0" iyy="0.025" iyz="0" izz="0.0153"/>
		</inertial>
	</link>

	<!-- Front Left Wheel -->
	<joint name="front_left_wheel_joint" type="continuous">
		<axis xyz="0 0 1" />
		<origin xyz="0 0.125029 -0.025" rpy="-1.5707 0 0"/>
		<parent link="front_left_wheel_steering_link" />
		<child link="front_left_wheel_link" />
	</joint>

	<link name="front_left_wheel_link">
		<visual>
			<geometry>
				<cylinder length="0.07" radius="0.3"/>
			</geometry>
			<material name="black">
				<color rgba="0.2 0.2 0.2 1" />
			</material>
		</visual>
		<collision>
			<geometry>
				<cylinder length="0.07" radius="0.3"/>
			</geometry>
			<material name="black">
				<color rgba="0.2 0.2 0.2 1" />
			</material>
		</collision>
		<inertial>
			<mass value="5"/>
			<inertia ixx="0.11454" ixy="0" ixz="0" iyy="0.11454" iyz="0" izz="0.225"/>
		</inertial>
	</link>

	<!-- Front Right Steering -->
	<joint name="front_right_wheel_steering_joint" type="revolute">
		<origin xyz="${front_wheel_x} -0.5 0.02" rpy="0 0 0"/>
		<axis xyz="0 0 1" />
		<parent link="chassis_link" />
		<child link="front_right_wheel_steering_link" />
		<limit lower="-0.25" upper="0.25" velocity="1.0" effort="25" />
	</joint>

	<link name="front_right_wheel_steering_link">
		<visual>
			<geometry>
				<cylinder length="0.1" radius="0.03"/>
			</geometry>
			<material name="white">
				<color rgba="1 1 1 0.5" />
			</material>
		</visual>
		<collision>
			<geometry>
				<cylinder length="0.1" radius="0.03"/>
			</geometry>
			<material name="white">
				<color rgba="1 1 1 0.5" />
			</material>
		</collision>
		<inertial>
			<mass value="0.5"/>
			<inertia ixx="0.0153" ixy="0" ixz="0" iyy="0.025" iyz="0" izz="0.0153"/>
		</inertial>
	</link>

	<!-- Front Right Wheel -->
	<joint name="front_right_wheel_joint" type="continuous">
		<axis xyz="0 0 1" />
		<origin xyz="0 -0.125029 -0.025" rpy="-1.5707 0 0"/>
		<parent link="front_right_wheel_steering_link" />
		<child link="front_right_wheel_link" />
	</joint>

	<link name="front_right_wheel_link">
		<visual>
			<geometry>
				<cylinder length="0.07" radius="0.3"/>
			</geometry>
			<material name="black">
				<color rgba="0.2 0.2 0.2 1" />
			</material>
		</visual>
		<collision>
			<geometry>
				<cylinder length="0.07" radius="0.3"/>
			</geometry>
			<material name="black">
				<color rgba="0.2 0.2 0.2 1" />
			</material>
		</collision>
		<inertial>
			<mass value="5"/>
			<inertia ixx="0.11454" ixy="0" ixz="0" iyy="0.11454" iyz="0" izz="0.225"/>
		</inertial>
	</link>

	<!-- Rear Left Wheel -->
	<joint name="rear_left_wheel_joint" type="continuous">
		<origin xyz="${rear_wheel_x} 0.625029 -0.025" rpy="-1.5707 0 0"/>
		<axis xyz="0 0 1" />
		<parent link="chassis_link" />
		<child link="rear_left_wheel_link" />
	</joint>

	<link name="rear_left_wheel_link">
		<visual>
			<geometry>
				<cylinder length="0.07" radius="0.3"/>
			</geometry>
			<material name="black">
				<color rgba="0.2 0.2 0.2 1" />
			</material>
		</visual>
		<collision>
			<geometry>
				<cylinder length="0.07" radius="0.3"/>
			</geometry>
			<material name="black">
				<color rgba="0.2 0.2 0.2 1" />
			</material>
		</collision>
		<inertial>
			<mass value="5"/>
			<inertia ixx="0.11454" ixy="0" ixz="0" iyy="0.11454" iyz="0" izz="0.225"/>
		</inertial>
	</link>

	<!-- Rear Right Wheel -->
	<joint name="rear_right_wheel_joint" type="continuous">
		<axis xyz="0 0 1" />
		<origin xyz="${rear_wheel_x} -0.625029 -0.025" rpy="-1.5707 0 0"/>
		<parent link="chassis_link" />
		<child link="rear_right_wheel_link" />
	</joint>

	<link name="rear_right_wheel_link">
		<visual>
			<geometry>
				<cylinder length="0.07" radius="0.3"/>
			</geometry>
			<material name="black">
				<color rgba="0.2 0.2 0.2 1" />
			</material>
		</visual>
		<collision>
			<geometry>
				<cylinder length="0.07" radius="0.3"/>
			</geometry>
			<material name="black">
				<color rgba="0.2 0.2 0.2 1" />
			</material>
		</collision>
		<inertial>
			<mass value="5"/>
			<inertia ixx="0.11454" ixy="0" ixz="0" iyy="0.11454" iyz="0" izz="0.225"/>
		</inertial>
	</link>

	<!-- IMU -->
	<joint name="imu_joint" type="continuous">
		<parent link="chassis_link" />
		<axis xyz="0 0 1" />
		<child link="imu_link" />
		<origin xyz="-0.05 0 1.305" />
	</joint>

	<link name="imu_link">
		<inertial>
			<mass value="0.425" />
			<inertia ixx="0.000361" ixy="0" ixz="0" iyy="0.000361" iyz="0" izz="0.00034"/>
		</inertial>
	</link>

	<!-- LiDAR -->
	<joint name="lidar_joint" type="continuous">
		<origin xyz="-0.05 0 1.305" />
		<axis xyz="0 0 1" />
		<parent link="chassis_link" />
		<child link="lidar_link" />
	</joint>

	<link name="lidar_link">
		<visual>
			<origin xyz="0 0 0.03675" />
			<geometry>
				<cylinder length="0.0735" radius="0.04" />
			</geometry>
			<material name="orange">
				<color rgba="0.5 0.4 0.3 1" />
			</material>
		</visual>
		<collision>
			<origin xyz="0 0 0.03675" />
			<geometry>
				<cylinder length="0.0735" radius="0.04" />
			</geometry>
			<material name="orange">
				<color rgba="0.5 0.4 0.3 1" />
			</material>
		</collision>
		<inertial>
			<mass value="0.425" />
			<inertia ixx="0.000361" ixy="0" ixz="0" iyy="0.000361" iyz="0" izz="0.00034"/>
		</inertial>
	</link>
	<xacro:include filename="gz_plugins.xacro"/>
</robot>
