<?xml version="1.0" ?>
<robot xmlns:xacro="http://ros.org/wiki/xacro">
	<!-- Make a macro function with arguments (parent, direction (to keep wheel rotation consistent)) -->
	<xacro:property name="radius" value="0.3" />
	<xacro:property name="thickness" value="0.07" />

	<xacro:macro name="wheel" params="suffix direction parent *origin">
		<joint name="${suffix}_${direction}_wheel_joint" type="continuous">
			<xacro:insert_block name="origin"/>
			<parent link="${parent}"/>
			<child link="${suffix}_${direction}_wheel_link"/>
			<axis xyz="0 0 1"/>
		</joint>

		<link name="${suffix}_${direction}_wheel_link">
			<visual>
				<geometry>
					<cylinder radius="${radius}" length="${thickness}" />
				</geometry>
				<origin xyz="0.0 0.0 0.0" rpy="0 0 0" />
				<material name="blue">
					<color rgba="0 0.5 0.25 0.5"/>
				</material>
			</visual>
					<!-- Change to sphere later if the car drives a bit rough -->
			<collision>
				<geometry>
					<cylinder radius="${radius}" length="${thickness}" />
				</geometry>
				<origin xyz="0.0 0.0 0.0" rpy="0 0 0" />
			</collision>
			<inertial>
				<mass value="5.0"/>
				<origin xyz="0.0 0.0 0.0" rpy="0 0 0" />
				<inertia ixx="0.452" ixy="0.0" ixz="0.0" iyy="0.452" iyz="0.0" izz="0.9" />
			</inertial>
		</link>
	</xacro:macro>
</robot>
